<?xml version="1.0" ?>
<!-- =================================================================================== -->
<!-- |    This document was autogenerated by xacro from robot.xacro                    | -->
<!-- |    EDITING THIS FILE BY HAND IS NOT RECOMMENDED                                 | -->
<!-- =================================================================================== -->
<robot name="laikago">
  <!--    <xacro:property name="J1" value="0.5"/>-->
  <!--    <xacro:property name="L1" value="0.2"/>-->
  <!--    <xacro:property name="J2" value="${hip_mass}"/>-->
  <!--    <xacro:property name="L2" value="${thigh_mass}"/>-->
  <!--    <xacro:property name="J3" value="0.0"/>-->
  <!--    <xacro:property name="L3" value="0.0"/>-->
  <!--    <xacro:property name="J4" value="0.0"/>-->
  <!--    <xacro:property name="L4" value="${calf_mass * 1}"/>-->
  <!--    <xacro:property name="J5" value="0.0"/>-->
  <!--    <xacro:property name="L5" value="0.0"/>-->
  <!--    <xacro:property name="J6" value="0.0"/>-->
  <!--    <xacro:property name="hand" value="0.0"/>-->
  <material name="black">
    <color rgba="0.0 0.0 0.0 1.0"/>
  </material>
  <material name="blue">
    <color rgba="0.0 0.0 0.8 1.0"/>
  </material>
  <material name="green">
    <color rgba="0.0 0.8 0.0 1.0"/>
  </material>
  <material name="grey">
    <color rgba="0.2 0.2 0.2 1.0"/>
  </material>
  <material name="silver">
    <color rgba="0.9137254901960784 0.9137254901960784 0.8470588235294118 1.0"/>
  </material>
  <material name="orange">
    <color rgba="1.0 0.4235294117647059 0.0392156862745098 1.0"/>
  </material>
  <material name="brown">
    <color rgba="0.8705882352941177 0.8117647058823529 0.7647058823529411 1.0"/>
  </material>
  <material name="red">
    <color rgba="0.8 0.0 0.0 1.0"/>
  </material>
  <material name="white">
    <color rgba="1.0 1.0 1.0 1.0"/>
  </material>
  <!-- <xacro:include filename="$(find laikago_description)/xacro/transmission.xacro"/> -->
  <!-- <xacro:include filename="$(find laikago_description)/xacro/transmission.xacro"/> -->
  <!-- <xacro:include filename="gazebo.xacro"/> -->
  <!-- <link name="base">
        <visual>
            <origin rpy="0 0 0" xyz="0 0 0"/>
            <geometry>
                <box size="0.001 0.001 0.001"/>
            </geometry>
        </visual>
    </link>

    <joint name="floating_base" type="fixed">
        <origin rpy="0 0 0" xyz="0 0 0"/>
        <parent link="base"/>
        <child link="trunk"/>
    </joint> -->
  <link name="trunk">
    <!-- <visual>
            <origin rpy="0 0 0" xyz="0 0 0"/>
            <geometry>
                <mesh filename="package://laikago_description/meshes/trunk.dae" scale="1 1 1"/>
            </geometry>
            <material name="orange"/>
        </visual> -->
    <visual>
      <origin rpy="0 0 0" xyz="0 0 0.0"/>
      <geometry>
        <box size="0.375 0.2 0.168"/>
      </geometry>
    </visual>
    <visual>
      <origin rpy="0 0 0" xyz="0.09375 0 0.168"/>
      <geometry>
        <box size="0.1875 0.2 0.168"/>
      </geometry>
    </visual>
    <visual>
      <origin rpy="1.5707963267948966 0 0" xyz="0.1875 0.0725 0.168"/>
      <geometry>
        <cylinder length="0.055" radius="0.036"/>
      </geometry>
    </visual>
    <visual>
      <origin rpy="1.5707963267948966 0 0" xyz="0.1875 -0.0725 0.168"/>
      <geometry>
        <cylinder length="0.055" radius="0.036"/>
      </geometry>
    </visual>
    <visual>
      <origin rpy="1.5707963267948966 0 0" xyz="-0.1875 0.0725 0.0"/>
      <geometry>
        <cylinder length="0.055" radius="0.036"/>
      </geometry>
    </visual>
    <visual>
      <origin rpy="1.5707963267948966 0 0" xyz="-0.1875 -0.0725 0.0"/>
      <geometry>
        <cylinder length="0.055" radius="0.036"/>
      </geometry>
    </visual>
    <collision>
      <origin rpy="0 0 0" xyz="0 0 0.0"/>
      <geometry>
        <box size="0.375 0.2 0.168"/>
      </geometry>
    </collision>
    <collision>
      <origin rpy="0 0 0" xyz="0.09375 0 0.168"/>
      <geometry>
        <box size="0.1875 0.2 0.168"/>
      </geometry>
    </collision>
    <inertial>
      <origin rpy="0 0 0" xyz="0.0 0.0 0.0"/>
      <mass value="10.0"/>
      <inertia ixx="0.08" ixy="0.0" ixz="0.0" iyy="0.25" iyz="-0.0" izz="0.25"/>
    </inertial>
  </link>
  <joint name="imu_joint" type="fixed">
    <parent link="trunk"/>
    <child link="imu_link"/>
    <origin rpy="0 0 0" xyz="0 0 0"/>
  </joint>
  <link name="imu_link">
    <inertial>
      <mass value="0.001"/>
      <origin rpy="0 0 0" xyz="0 0 0"/>
      <inertia ixx="0.0001" ixy="0" ixz="0" iyy="0.000001" iyz="0" izz="0.0001"/>
    </inertial>
    <visual>
      <origin rpy="0 0 0" xyz="0 0 0"/>
      <geometry>
        <box size="0.001 0.001 0.001"/>
      </geometry>
      <material name="red"/>
    </visual>
    <collision>
      <origin rpy="0 0 0" xyz="0 0 0"/>
      <geometry>
        <box size=".001 .001 .001"/>
      </geometry>
    </collision>
  </link>
  <joint name="FR_hip_joint" type="revolute">
    <origin rpy="0 0 0" xyz="0.1875 -0.0725 0.168"/>
    <parent link="trunk"/>
    <child link="FR_hip"/>
    <axis xyz="0 1 0"/>
    <dynamics damping="0" friction="0"/>
    <limit effort="100.954" lower="-1.0471975511965976" upper="0.8726646259971648" velocity="27"/>
  </joint>
  <link name="FR_hip">
    <!-- <visual>
                <xacro:if value="${(mirror_dae == True) and (front_hind_dae == True)}">
                    <origin rpy="0 0 0" xyz="0 0 0"/>
                </xacro:if>
                <xacro:if value="${(mirror_dae == False) and (front_hind_dae == True)}">
                    <origin rpy="${PI} 0 0" xyz="0 0 0"/>
                </xacro:if>
                <xacro:if value="${(mirror_dae == True) and (front_hind_dae == False)}">
                    <origin rpy="0 ${PI} 0" xyz="0 0 0"/>
                </xacro:if>
                <xacro:if value="${(mirror_dae == False) and (front_hind_dae == False)}">
                    <origin rpy="${PI} ${PI} 0" xyz="0 0 0"/>
                </xacro:if>
                <geometry>
                    <mesh filename="package://laikago_description/meshes/hip.dae" scale="1 1 1"/>
                </geometry>
                <material name="orange"/>
            </visual> -->
    <visual>
      <origin rpy="0 1.5707963267948966 0" xyz="0 -0.0775 0"/>
      <geometry>
        <cylinder length="0.055" radius="0.036"/>
      </geometry>
    </visual>
    <collision>
      <origin rpy="0 1.5707963267948966 0" xyz="0 -0.0775 0"/>
      <geometry>
        <cylinder length="0.055" radius="0.036"/>
      </geometry>
    </collision>
    <inertial>
      <origin rpy="0 0 0" xyz="-0.001568 0.008134 0.000864"/>
      <mass value="0.55"/>
      <inertia ixx="0.000822113" ixy="4.982e-06" ixz="-3.672e-05" iyy="0.000983196" iyz="-2.811e-06" izz="0.000864753"/>
    </inertial>
  </link>
  <joint name="FR_thigh_joint" type="revolute">
    <origin rpy="0 0 0" xyz="0 -0.0775 0"/>
    <parent link="FR_hip"/>
    <child link="FR_thigh"/>
    <axis xyz="1 0 0"/>
    <dynamics damping="0" friction="0"/>
    <limit effort="100" lower="-0.5235987755982988" upper="3.9269908169872414" velocity="20.794"/>
  </joint>
  <link name="FR_thigh">
    <!-- <visual>
                <origin rpy="0 0 0" xyz="0 0 0"/>
                <geometry>
                    <xacro:if value="${mirror_dae == True}">
                        <mesh filename="package://laikago_description/meshes/thigh.dae" scale="1 1 1"/>
                    </xacro:if>
                    <xacro:if value="${mirror_dae == False}">
                        <mesh filename="package://laikago_description/meshes/thigh_mirror.dae" scale="1 1 1"/>
                    </xacro:if>
                </geometry>
                <material name="orange"/>
            </visual> -->
    <visual>
      <origin rpy="0 1.5707963267948966 0" xyz="0 0 -0.151"/>
      <geometry>
        <box size="0.302 0.034 0.043"/>
      </geometry>
    </visual>
    <collision>
      <origin rpy="0 1.5707963267948966 0" xyz="0 0 -0.151"/>
      <geometry>
        <box size="0.302 0.034 0.043"/>
      </geometry>
    </collision>
    <inertial>
      <origin rpy="0 0 0" xyz="-0.000482 -0.02001 -0.1"/>
      <mass value="1.6"/>
      <inertia ixx="0.00991611" ixy="-1.0388e-05" ixz="0.000250428" iyy="0.009280083" iyz="8.511e-05" izz="0.00178256"/>
    </inertial>
  </link>
  <joint name="FR_calf_joint" type="revolute">
    <origin rpy="0 0 0" xyz="0 0 -0.302"/>
    <parent link="FR_thigh"/>
    <child link="FR_calf"/>
    <axis xyz="0 1 0"/>
    <dynamics damping="0" friction="0"/>
    <limit effort="100" lower="-2.775073510670984" upper="-0.6108652381980153" velocity="20.794"/>
  </joint>
  <link name="FR_calf">
    <!-- <visual>
                <origin rpy="0 0 0" xyz="0 0 0"/>
                <geometry>
                    <mesh filename="package://laikago_description/meshes/calf.dae" scale="1 1 1"/>
                </geometry>
                <material name="orange"/>
            </visual> -->
    <visual>
      <origin rpy="0 1.5707963267948966 0" xyz="0 0 -0.151"/>
      <geometry>
        <box size="0.302 0.016 0.016"/>
      </geometry>
    </visual>
    <collision>
      <origin rpy="0 1.5707963267948966 0" xyz="0 0 -0.151"/>
      <geometry>
        <box size="0.302 0.016 0.016"/>
      </geometry>
    </collision>
    <inertial>
      <origin rpy="0 0 0" xyz="-0.002196 -0.000381 -0.2"/>
      <mass value="1.7"/>
      <inertia ixx="0.006181961" ixy="2.37e-07" ixz="-2.985e-06" iyy="0.006196546" iyz="5.138e-06" izz="3.4774e-05"/>
    </inertial>
  </link>
  <joint name="FR_foot_fixed" type="fixed">
    <origin rpy="0 0 0" xyz="0 0 -0.302"/>
    <parent link="FR_calf"/>
    <child link="FR_foot"/>
  </joint>
  <link name="FR_foot">
    <!-- <visual>
                <origin rpy="0 0 0" xyz="0 0 0"/>
                <geometry>
                    <sphere radius="${foot_radius-0.01}"/>
                </geometry>
                <material name="orange"/>
            </visual> -->
    <visual>
      <origin rpy="0 0 0" xyz="0 0 0"/>
      <geometry>
        <sphere radius="0.0265"/>
      </geometry>
    </visual>
    <collision>
      <origin rpy="0 0 0" xyz="0 0 0"/>
      <geometry>
        <sphere radius="0.0265"/>
      </geometry>
    </collision>
    <inertial>
      <mass value="0.06"/>
      <inertia ixx="1.6853999999999998e-05" ixy="0.0" ixz="0.0" iyy="1.6853999999999998e-05" iyz="0.0" izz="1.6853999999999998e-05"/>
    </inertial>
  </link>
  <!-- <xacro:leg_transmission name="${name}"/> -->
  <joint name="FL_hip_joint" type="revolute">
    <origin rpy="0 0 0" xyz="0.1875 0.0725 0.168"/>
    <parent link="trunk"/>
    <child link="FL_hip"/>
    <axis xyz="0 1 0"/>
    <dynamics damping="0" friction="0"/>
    <limit effort="100.954" lower="-0.8726646259971648" upper="1.0471975511965976" velocity="27"/>
  </joint>
  <link name="FL_hip">
    <!-- <visual>
                <xacro:if value="${(mirror_dae == True) and (front_hind_dae == True)}">
                    <origin rpy="0 0 0" xyz="0 0 0"/>
                </xacro:if>
                <xacro:if value="${(mirror_dae == False) and (front_hind_dae == True)}">
                    <origin rpy="${PI} 0 0" xyz="0 0 0"/>
                </xacro:if>
                <xacro:if value="${(mirror_dae == True) and (front_hind_dae == False)}">
                    <origin rpy="0 ${PI} 0" xyz="0 0 0"/>
                </xacro:if>
                <xacro:if value="${(mirror_dae == False) and (front_hind_dae == False)}">
                    <origin rpy="${PI} ${PI} 0" xyz="0 0 0"/>
                </xacro:if>
                <geometry>
                    <mesh filename="package://laikago_description/meshes/hip.dae" scale="1 1 1"/>
                </geometry>
                <material name="orange"/>
            </visual> -->
    <visual>
      <origin rpy="0 1.5707963267948966 0" xyz="0 0.0775 0"/>
      <geometry>
        <cylinder length="0.055" radius="0.036"/>
      </geometry>
    </visual>
    <collision>
      <origin rpy="0 1.5707963267948966 0" xyz="0 0.0775 0"/>
      <geometry>
        <cylinder length="0.055" radius="0.036"/>
      </geometry>
    </collision>
    <inertial>
      <origin rpy="0 0 0" xyz="-0.001568 -0.008134 0.000864"/>
      <mass value="0.55"/>
      <inertia ixx="0.000822113" ixy="-4.982e-06" ixz="-3.672e-05" iyy="0.000983196" iyz="2.811e-06" izz="0.000864753"/>
    </inertial>
  </link>
  <joint name="FL_thigh_joint" type="revolute">
    <origin rpy="0 0 0" xyz="0 0.0775 0"/>
    <parent link="FL_hip"/>
    <child link="FL_thigh"/>
    <axis xyz="1 0 0"/>
    <dynamics damping="0" friction="0"/>
    <limit effort="100" lower="-0.5235987755982988" upper="3.9269908169872414" velocity="20.794"/>
  </joint>
  <link name="FL_thigh">
    <!-- <visual>
                <origin rpy="0 0 0" xyz="0 0 0"/>
                <geometry>
                    <xacro:if value="${mirror_dae == True}">
                        <mesh filename="package://laikago_description/meshes/thigh.dae" scale="1 1 1"/>
                    </xacro:if>
                    <xacro:if value="${mirror_dae == False}">
                        <mesh filename="package://laikago_description/meshes/thigh_mirror.dae" scale="1 1 1"/>
                    </xacro:if>
                </geometry>
                <material name="orange"/>
            </visual> -->
    <visual>
      <origin rpy="0 1.5707963267948966 0" xyz="0 0 -0.151"/>
      <geometry>
        <box size="0.302 0.034 0.043"/>
      </geometry>
    </visual>
    <collision>
      <origin rpy="0 1.5707963267948966 0" xyz="0 0 -0.151"/>
      <geometry>
        <box size="0.302 0.034 0.043"/>
      </geometry>
    </collision>
    <inertial>
      <origin rpy="0 0 0" xyz="-0.000482 0.02001 -0.1"/>
      <mass value="1.6"/>
      <inertia ixx="0.00991611" ixy="1.0388e-05" ixz="0.000250428" iyy="0.009280083" iyz="-8.511e-05" izz="0.00178256"/>
    </inertial>
  </link>
  <joint name="FL_calf_joint" type="revolute">
    <origin rpy="0 0 0" xyz="0 0 -0.302"/>
    <parent link="FL_thigh"/>
    <child link="FL_calf"/>
    <axis xyz="0 1 0"/>
    <dynamics damping="0" friction="0"/>
    <limit effort="100" lower="-2.775073510670984" upper="-0.6108652381980153" velocity="20.794"/>
  </joint>
  <link name="FL_calf">
    <!-- <visual>
                <origin rpy="0 0 0" xyz="0 0 0"/>
                <geometry>
                    <mesh filename="package://laikago_description/meshes/calf.dae" scale="1 1 1"/>
                </geometry>
                <material name="orange"/>
            </visual> -->
    <visual>
      <origin rpy="0 1.5707963267948966 0" xyz="0 0 -0.151"/>
      <geometry>
        <box size="0.302 0.016 0.016"/>
      </geometry>
    </visual>
    <collision>
      <origin rpy="0 1.5707963267948966 0" xyz="0 0 -0.151"/>
      <geometry>
        <box size="0.302 0.016 0.016"/>
      </geometry>
    </collision>
    <inertial>
      <origin rpy="0 0 0" xyz="-0.002196 -0.000381 -0.2"/>
      <mass value="1.7"/>
      <inertia ixx="0.006181961" ixy="2.37e-07" ixz="-2.985e-06" iyy="0.006196546" iyz="5.138e-06" izz="3.4774e-05"/>
    </inertial>
  </link>
  <joint name="FL_foot_fixed" type="fixed">
    <origin rpy="0 0 0" xyz="0 0 -0.302"/>
    <parent link="FL_calf"/>
    <child link="FL_foot"/>
  </joint>
  <link name="FL_foot">
    <!-- <visual>
                <origin rpy="0 0 0" xyz="0 0 0"/>
                <geometry>
                    <sphere radius="${foot_radius-0.01}"/>
                </geometry>
                <material name="orange"/>
            </visual> -->
    <visual>
      <origin rpy="0 0 0" xyz="0 0 0"/>
      <geometry>
        <sphere radius="0.0265"/>
      </geometry>
    </visual>
    <collision>
      <origin rpy="0 0 0" xyz="0 0 0"/>
      <geometry>
        <sphere radius="0.0265"/>
      </geometry>
    </collision>
    <inertial>
      <mass value="0.06"/>
      <inertia ixx="1.6853999999999998e-05" ixy="0.0" ixz="0.0" iyy="1.6853999999999998e-05" iyz="0.0" izz="1.6853999999999998e-05"/>
    </inertial>
  </link>
  <!-- <xacro:leg_transmission name="${name}"/> -->
  <joint name="RR_hip_joint" type="revolute">
    <origin rpy="0 0 0" xyz="-0.1875 -0.0725 0.0"/>
    <parent link="trunk"/>
    <child link="RR_hip"/>
    <axis xyz="0 1 0"/>
    <dynamics damping="0" friction="0"/>
    <limit effort="100.954" lower="-1.0471975511965976" upper="0.8726646259971648" velocity="27"/>
  </joint>
  <link name="RR_hip">
    <!-- <visual>
                <xacro:if value="${(mirror_dae == True) and (front_hind_dae == True)}">
                    <origin rpy="0 0 0" xyz="0 0 0"/>
                </xacro:if>
                <xacro:if value="${(mirror_dae == False) and (front_hind_dae == True)}">
                    <origin rpy="${PI} 0 0" xyz="0 0 0"/>
                </xacro:if>
                <xacro:if value="${(mirror_dae == True) and (front_hind_dae == False)}">
                    <origin rpy="0 ${PI} 0" xyz="0 0 0"/>
                </xacro:if>
                <xacro:if value="${(mirror_dae == False) and (front_hind_dae == False)}">
                    <origin rpy="${PI} ${PI} 0" xyz="0 0 0"/>
                </xacro:if>
                <geometry>
                    <mesh filename="package://laikago_description/meshes/hip.dae" scale="1 1 1"/>
                </geometry>
                <material name="orange"/>
            </visual> -->
    <visual>
      <origin rpy="0 1.5707963267948966 0" xyz="0 -0.0775 0"/>
      <geometry>
        <cylinder length="0.055" radius="0.036"/>
      </geometry>
    </visual>
    <collision>
      <origin rpy="0 1.5707963267948966 0" xyz="0 -0.0775 0"/>
      <geometry>
        <cylinder length="0.055" radius="0.036"/>
      </geometry>
    </collision>
    <inertial>
      <origin rpy="0 0 0" xyz="0.001568 0.008134 0.000864"/>
      <mass value="1.096"/>
      <inertia ixx="0.000822113" ixy="-4.982e-06" ixz="3.672e-05" iyy="0.000983196" iyz="-2.811e-06" izz="0.000864753"/>
    </inertial>
  </link>
  <joint name="RR_thigh_joint" type="revolute">
    <origin rpy="0 0 0" xyz="0 -0.0775 0"/>
    <parent link="RR_hip"/>
    <child link="RR_thigh"/>
    <axis xyz="1 0 0"/>
    <dynamics damping="0" friction="0"/>
    <limit effort="100" lower="-0.5235987755982988" upper="3.9269908169872414" velocity="20.794"/>
  </joint>
  <link name="RR_thigh">
    <!-- <visual>
                <origin rpy="0 0 0" xyz="0 0 0"/>
                <geometry>
                    <xacro:if value="${mirror_dae == True}">
                        <mesh filename="package://laikago_description/meshes/thigh.dae" scale="1 1 1"/>
                    </xacro:if>
                    <xacro:if value="${mirror_dae == False}">
                        <mesh filename="package://laikago_description/meshes/thigh_mirror.dae" scale="1 1 1"/>
                    </xacro:if>
                </geometry>
                <material name="orange"/>
            </visual> -->
    <visual>
      <origin rpy="0 1.5707963267948966 0" xyz="0 0 -0.1125"/>
      <geometry>
        <box size="0.225 0.034 0.043"/>
      </geometry>
    </visual>
    <collision>
      <origin rpy="0 1.5707963267948966 0" xyz="0 0 -0.1125"/>
      <geometry>
        <box size="0.225 0.034 0.043"/>
      </geometry>
    </collision>
    <inertial>
      <origin rpy="0 0 0" xyz="-0.000482 -0.02001 -0.031996"/>
      <mass value="1.528"/>
      <inertia ixx="0.00991611" ixy="-1.0388e-05" ixz="0.000250428" iyy="0.009280083" iyz="8.511e-05" izz="0.00178256"/>
    </inertial>
  </link>
  <joint name="RR_calf_joint" type="revolute">
    <origin rpy="0 0 0" xyz="0 0 -0.225"/>
    <parent link="RR_thigh"/>
    <child link="RR_calf"/>
    <axis xyz="0 1 0"/>
    <dynamics damping="0" friction="0"/>
    <limit effort="100" lower="-2.775073510670984" upper="-0.6108652381980153" velocity="20.794"/>
  </joint>
  <link name="RR_calf">
    <!-- <visual>
                <origin rpy="0 0 0" xyz="0 0 0"/>
                <geometry>
                    <mesh filename="package://laikago_description/meshes/calf.dae" scale="1 1 1"/>
                </geometry>
                <material name="orange"/>
            </visual> -->
    <visual>
      <origin rpy="0 1.5707963267948966 0" xyz="0 0 -0.1125"/>
      <geometry>
        <box size="0.225 0.016 0.016"/>
      </geometry>
    </visual>
    <collision>
      <origin rpy="0 1.5707963267948966 0" xyz="0 0 -0.1125"/>
      <geometry>
        <box size="0.225 0.016 0.016"/>
      </geometry>
    </collision>
    <inertial>
      <origin rpy="0 0 0" xyz="-0.002196 -0.000381 -0.12338"/>
      <mass value="0.241"/>
      <inertia ixx="0.006181961" ixy="2.37e-07" ixz="-2.985e-06" iyy="0.006196546" iyz="5.138e-06" izz="3.4774e-05"/>
    </inertial>
  </link>
  <joint name="RR_foot_fixed" type="fixed">
    <origin rpy="0 0 0" xyz="0 0 -0.225"/>
    <parent link="RR_calf"/>
    <child link="RR_foot"/>
  </joint>
  <link name="RR_foot">
    <!-- <visual>
                <origin rpy="0 0 0" xyz="0 0 0"/>
                <geometry>
                    <sphere radius="${foot_radius-0.01}"/>
                </geometry>
                <material name="orange"/>
            </visual> -->
    <visual>
      <origin rpy="0 0 0" xyz="0 0 0"/>
      <geometry>
        <sphere radius="0.0265"/>
      </geometry>
    </visual>
    <collision>
      <origin rpy="0 0 0" xyz="0 0 0"/>
      <geometry>
        <sphere radius="0.0265"/>
      </geometry>
    </collision>
    <inertial>
      <mass value="0.06"/>
      <inertia ixx="1.6853999999999998e-05" ixy="0.0" ixz="0.0" iyy="1.6853999999999998e-05" iyz="0.0" izz="1.6853999999999998e-05"/>
    </inertial>
  </link>
  <!-- <xacro:leg_transmission name="${name}"/> -->
  <joint name="RL_hip_joint" type="revolute">
    <origin rpy="0 0 0" xyz="-0.1875 0.0725 0.0"/>
    <parent link="trunk"/>
    <child link="RL_hip"/>
    <axis xyz="0 1 0"/>
    <dynamics damping="0" friction="0"/>
    <limit effort="100.954" lower="-0.8726646259971648" upper="1.0471975511965976" velocity="27"/>
  </joint>
  <link name="RL_hip">
    <!-- <visual>
                <xacro:if value="${(mirror_dae == True) and (front_hind_dae == True)}">
                    <origin rpy="0 0 0" xyz="0 0 0"/>
                </xacro:if>
                <xacro:if value="${(mirror_dae == False) and (front_hind_dae == True)}">
                    <origin rpy="${PI} 0 0" xyz="0 0 0"/>
                </xacro:if>
                <xacro:if value="${(mirror_dae == True) and (front_hind_dae == False)}">
                    <origin rpy="0 ${PI} 0" xyz="0 0 0"/>
                </xacro:if>
                <xacro:if value="${(mirror_dae == False) and (front_hind_dae == False)}">
                    <origin rpy="${PI} ${PI} 0" xyz="0 0 0"/>
                </xacro:if>
                <geometry>
                    <mesh filename="package://laikago_description/meshes/hip.dae" scale="1 1 1"/>
                </geometry>
                <material name="orange"/>
            </visual> -->
    <visual>
      <origin rpy="0 1.5707963267948966 0" xyz="0 0.0775 0"/>
      <geometry>
        <cylinder length="0.055" radius="0.036"/>
      </geometry>
    </visual>
    <collision>
      <origin rpy="0 1.5707963267948966 0" xyz="0 0.0775 0"/>
      <geometry>
        <cylinder length="0.055" radius="0.036"/>
      </geometry>
    </collision>
    <inertial>
      <origin rpy="0 0 0" xyz="0.001568 -0.008134 0.000864"/>
      <mass value="1.096"/>
      <inertia ixx="0.000822113" ixy="4.982e-06" ixz="3.672e-05" iyy="0.000983196" iyz="2.811e-06" izz="0.000864753"/>
    </inertial>
  </link>
  <joint name="RL_thigh_joint" type="revolute">
    <origin rpy="0 0 0" xyz="0 0.0775 0"/>
    <parent link="RL_hip"/>
    <child link="RL_thigh"/>
    <axis xyz="1 0 0"/>
    <dynamics damping="0" friction="0"/>
    <limit effort="100" lower="-0.5235987755982988" upper="3.9269908169872414" velocity="20.794"/>
  </joint>
  <link name="RL_thigh">
    <!-- <visual>
                <origin rpy="0 0 0" xyz="0 0 0"/>
                <geometry>
                    <xacro:if value="${mirror_dae == True}">
                        <mesh filename="package://laikago_description/meshes/thigh.dae" scale="1 1 1"/>
                    </xacro:if>
                    <xacro:if value="${mirror_dae == False}">
                        <mesh filename="package://laikago_description/meshes/thigh_mirror.dae" scale="1 1 1"/>
                    </xacro:if>
                </geometry>
                <material name="orange"/>
            </visual> -->
    <visual>
      <origin rpy="0 1.5707963267948966 0" xyz="0 0 -0.1125"/>
      <geometry>
        <box size="0.225 0.034 0.043"/>
      </geometry>
    </visual>
    <collision>
      <origin rpy="0 1.5707963267948966 0" xyz="0 0 -0.1125"/>
      <geometry>
        <box size="0.225 0.034 0.043"/>
      </geometry>
    </collision>
    <inertial>
      <origin rpy="0 0 0" xyz="-0.000482 0.02001 -0.031996"/>
      <mass value="1.528"/>
      <inertia ixx="0.00991611" ixy="1.0388e-05" ixz="0.000250428" iyy="0.009280083" iyz="-8.511e-05" izz="0.00178256"/>
    </inertial>
  </link>
  <joint name="RL_calf_joint" type="revolute">
    <origin rpy="0 0 0" xyz="0 0 -0.225"/>
    <parent link="RL_thigh"/>
    <child link="RL_calf"/>
    <axis xyz="0 1 0"/>
    <dynamics damping="0" friction="0"/>
    <limit effort="100" lower="-2.775073510670984" upper="-0.6108652381980153" velocity="20.794"/>
  </joint>
  <link name="RL_calf">
    <!-- <visual>
                <origin rpy="0 0 0" xyz="0 0 0"/>
                <geometry>
                    <mesh filename="package://laikago_description/meshes/calf.dae" scale="1 1 1"/>
                </geometry>
                <material name="orange"/>
            </visual> -->
    <visual>
      <origin rpy="0 1.5707963267948966 0" xyz="0 0 -0.1125"/>
      <geometry>
        <box size="0.225 0.016 0.016"/>
      </geometry>
    </visual>
    <collision>
      <origin rpy="0 1.5707963267948966 0" xyz="0 0 -0.1125"/>
      <geometry>
        <box size="0.225 0.016 0.016"/>
      </geometry>
    </collision>
    <inertial>
      <origin rpy="0 0 0" xyz="-0.002196 -0.000381 -0.12338"/>
      <mass value="0.241"/>
      <inertia ixx="0.006181961" ixy="2.37e-07" ixz="-2.985e-06" iyy="0.006196546" iyz="5.138e-06" izz="3.4774e-05"/>
    </inertial>
  </link>
  <joint name="RL_foot_fixed" type="fixed">
    <origin rpy="0 0 0" xyz="0 0 -0.225"/>
    <parent link="RL_calf"/>
    <child link="RL_foot"/>
  </joint>
  <link name="RL_foot">
    <!-- <visual>
                <origin rpy="0 0 0" xyz="0 0 0"/>
                <geometry>
                    <sphere radius="${foot_radius-0.01}"/>
                </geometry>
                <material name="orange"/>
            </visual> -->
    <visual>
      <origin rpy="0 0 0" xyz="0 0 0"/>
      <geometry>
        <sphere radius="0.0265"/>
      </geometry>
    </visual>
    <collision>
      <origin rpy="0 0 0" xyz="0 0 0"/>
      <geometry>
        <sphere radius="0.0265"/>
      </geometry>
    </collision>
    <inertial>
      <mass value="0.06"/>
      <inertia ixx="1.6853999999999998e-05" ixy="0.0" ixz="0.0" iyy="1.6853999999999998e-05" iyz="0.0" izz="1.6853999999999998e-05"/>
    </inertial>
  </link>
  <!-- <xacro:leg_transmission name="${name}"/> -->
</robot>

