<?xml version="1.0" ?>
<!-- =================================================================================== -->
<!-- |    This document was autogenerated by xacro from robot.xacro                    | -->
<!-- |    EDITING THIS FILE BY HAND IS NOT RECOMMENDED                                 | -->
<!-- =================================================================================== -->
<robot name="px3">
  <!-- dynamics inertial value -->
  <!-- arm -->
  <!-- <xacro:property name="J1" value="0.5"/>
    <xacro:property name="L1" value="0.2"/>
    <xacro:property name="J2" value="0.55"/>
    <xacro:property name="L2" value="0.35"/>
    <xacro:property name="J3" value="0.5"/>
    <xacro:property name="L3" value="0.2"/>
    <xacro:property name="J4" value="0.55"/>
    <xacro:property name="L4" value="0.35"/>
    <xacro:property name="J5" value="0.35"/>
    <xacro:property name="L5" value="0.15"/>
    <xacro:property name="J6" value="0.35"/>
    <xacro:property name="hand" value="0.5"/> -->
  <!--    <xacro:property name="J1" value="0.5"/>-->
  <!--    <xacro:property name="L1" value="0.2"/>-->
  <!--    <xacro:property name="J2" value="${hip_mass}"/>-->
  <!--    <xacro:property name="L2" value="${thigh_mass}"/>-->
  <!--    <xacro:property name="J3" value="0.0"/>-->
  <!--    <xacro:property name="L3" value="0.0"/>-->
  <!--    <xacro:property name="J4" value="0.0"/>-->
  <!--    <xacro:property name="L4" value="${calf_mass * 1}"/>-->
  <!--    <xacro:property name="J5" value="0.0"/>-->
  <!--    <xacro:property name="L5" value="0.0"/>-->
  <!--    <xacro:property name="J6" value="0.0"/>-->
  <!--    <xacro:property name="hand" value="0.0"/>-->
  <material name="black">
    <color rgba="0.0 0.0 0.0 1.0"/>
  </material>
  <material name="blue">
    <color rgba="0.0 0.0 0.8 1.0"/>
  </material>
  <material name="green">
    <color rgba="0.0 0.8 0.0 1.0"/>
  </material>
  <material name="grey">
    <color rgba="0.2 0.2 0.2 1.0"/>
  </material>
  <material name="silver">
    <color rgba="0.9137254901960784 0.9137254901960784 0.8470588235294118 1.0"/>
  </material>
  <material name="orange">
    <color rgba="1.0 0.4235294117647059 0.0392156862745098 0.5"/>
  </material>
  <material name="brown">
    <color rgba="0.8705882352941177 0.8117647058823529 0.7647058823529411 1.0"/>
  </material>
  <material name="red">
    <color rgba="0.8 0.0 0.0 1.0"/>
  </material>
  <material name="white">
    <color rgba="1.0 1.0 1.0 1.0"/>
  </material>
  <link name="base_link">
    <inertial>
      <origin rpy="0 0 0" xyz="0 0 0"/>
      <mass value="15.0"/>
      <inertia ixx="0.08" ixy="0.0" ixz="0.0" iyy="0.25" iyz="-0.0" izz="0.25"/>
    </inertial>
  </link>
  <joint name="floating_base" type="fixed">
    <origin rpy="0 0 0" xyz="0.1875 0 0.18"/>
    <parent link="base_link"/>
    <child link="trunk"/>
  </joint>
  <link name="trunk">
    <visual>
      <origin rpy="0 0 0" xyz="7.6e-3 0 14.64e-3"/>
      <geometry>
        <mesh filename="meshes/base.STL" scale="1 1 1"/>
      </geometry>
    </visual>
    <collision>
      <origin rpy="0 0 0" xyz="7.6e-3 0 14.64e-3"/>
      <geometry>
        <mesh filename="meshes/base.STL" scale="1 1 1"/>
      </geometry>
    </collision>
    <inertial>
      <origin rpy="0 0 0" xyz="0 0 0"/>
      <mass value="1"/>
      <inertia ixx="1e-3" ixy="0.0" ixz="0.0" iyy="1e-3" iyz="0.0" izz="1e-3"/>
    </inertial>
  </link>
  <joint name="leg0-fr_1_joint" type="revolute">
    <origin rpy="0 0 0" xyz="0.0 -0.0875 0.0"/>
    <parent link="trunk"/>
    <child link="fr_1"/>
    <axis xyz="0 1 0"/>
    <dynamics damping="0" friction="0"/>
    <limit effort="100" lower="-3.490658503988659" upper="3.490658503988659" velocity="30"/>
  </joint>
  <link name="fr_1">
    <visual>
      <origin rpy="0 0 0" xyz="0 0 0"/>
      <geometry>
        <mesh filename="meshes/fr_1.STL" scale="1 1 1"/>
      </geometry>
    </visual>
    <collision>
      <origin rpy="0 0 0" xyz="0 0 0"/>
      <geometry>
        <mesh filename="meshes/fr_1.STL" scale="1 1 1"/>
      </geometry>
    </collision>
    <inertial>
      <origin rpy="0 0 0" xyz="0 0 0"/>
      <mass value="1.35"/>
      <inertia ixx="1e-3" ixy="0.0" ixz="0.0" iyy="1e-3" iyz="0.0" izz="1e-3"/>
    </inertial>
  </link>
  <joint name="leg0-fr_2_joint" type="revolute">
    <origin rpy="0 0 0" xyz="0 -0.0775 0"/>
    <parent link="fr_1"/>
    <child link="fr_2"/>
    <axis xyz="1 0 0"/>
    <dynamics damping="0" friction="0"/>
    <limit effort="100" lower="-3.490658503988659" upper="3.490658503988659" velocity="30"/>
  </joint>
  <link name="fr_2">
    <visual>
      <origin rpy="0 0 0" xyz="0 0 0"/>
      <geometry>
        <mesh filename="meshes/fr_2.STL" scale="1 1 1"/>
      </geometry>
    </visual>
    <collision>
      <origin rpy="0 0 0" xyz="0 0 0"/>
      <geometry>
        <mesh filename="meshes/fr_2.STL" scale="1 1 1"/>
      </geometry>
    </collision>
    <inertial>
      <origin rpy="0 0 0" xyz="0 0 0"/>
      <mass value="0.9"/>
      <inertia ixx="1e-3" ixy="0.0" ixz="0.0" iyy="1e-3" iyz="0.0" izz="1e-3"/>
    </inertial>
  </link>
  <joint name="leg0-fr_3_joint" type="fixed">
    <origin rpy="0 0 0" xyz="0 0 -0.095"/>
    <parent link="fr_2"/>
    <child link="fr_3"/>
    &gt;

  </joint>
  <link name="fr_3">
    <visual>
      <origin rpy="0 0 0" xyz="0 0 0"/>
      <geometry>
        <mesh filename="meshes/fr_3.STL" scale="1 1 1"/>
      </geometry>
    </visual>
    <collision>
      <origin rpy="0 0 0" xyz="0 0 0"/>
      <geometry>
        <mesh filename="meshes/fr_3.STL" scale="1 1 1"/>
      </geometry>
    </collision>
    <inertial>
      <origin rpy="0 0 0" xyz="0 0 -0.10725"/>
      <mass value="1.7"/>
      <inertia ixx="1e-3" ixy="0.0" ixz="0.0" iyy="1e-3" iyz="0.0" izz="1e-3"/>
    </inertial>
  </link>
  <joint name="leg0-fr_4_joint" type="revolute">
    <origin rpy="0 0 0" xyz="0 0 -0.2145"/>
    <parent link="fr_3"/>
    <child link="fr_4"/>
    <axis xyz="0 1 0"/>
    <dynamics damping="0" friction="0"/>
    <limit effort="100" lower="-3.490658503988659" upper="3.490658503988659" velocity="30"/>
  </joint>
  <link name="fr_4">
    <visual>
      <origin rpy="0 0 0" xyz="0 0 0"/>
      <geometry>
        <mesh filename="meshes/fr_4.STL" scale="1 1 1"/>
      </geometry>
    </visual>
    <collision>
      <origin rpy="0 0 0" xyz="0 0 0"/>
      <geometry>
        <mesh filename="meshes/fr_4.STL" scale="1 1 1"/>
      </geometry>
    </collision>
    <inertial>
      <origin rpy="0 0 0" xyz="0 0 -0.11875"/>
      <mass value="2.1500000000000004"/>
      <inertia ixx="1e-3" ixy="0.0" ixz="0.0" iyy="1e-3" iyz="0.0" izz="1e-3"/>
    </inertial>
  </link>
  <joint name="leg0-fr_5_joint" type="fixed">
    <origin rpy="0 0 0" xyz="-0.0225 0.03 -0.2375"/>
    <parent link="fr_4"/>
    <child link="fr_5"/>
  </joint>
  <link name="fr_5">
    <visual>
      <origin rpy="0 0 0" xyz="0 0 0"/>
      <geometry>
        <mesh filename="meshes/fr_5.STL" scale="1 1 1"/>
      </geometry>
    </visual>
    <collision>
      <origin rpy="0 0 0" xyz="0 0 0"/>
      <geometry>
        <mesh filename="meshes/fr_5.STL" scale="1 1 1"/>
      </geometry>
    </collision>
    <inertial>
      <origin rpy="0 0 0" xyz="0 0 0"/>
      <mass value="0.48000000000000004"/>
      <inertia ixx="1e-3" ixy="0.0" ixz="0.0" iyy="1e-3" iyz="0.0" izz="1e-3"/>
    </inertial>
  </link>
  <joint name="leg0-fr_6_joint" type="fixed">
    <origin rpy="0 0 0" xyz="0 0 0.0405"/>
    <parent link="fr_5"/>
    <child link="fr_6"/>
  </joint>
  <link name="fr_6">
    <visual>
      <origin rpy="0 0 0" xyz="0 0 0"/>
      <geometry>
        <mesh filename="meshes/fr_6.STL" scale="1 1 1"/>
      </geometry>
    </visual>
    <collision>
      <origin rpy="0 0 0" xyz="0 0 0"/>
      <geometry>
        <mesh filename="meshes/fr_6.STL" scale="1 1 1"/>
      </geometry>
    </collision>
    <inertial>
      <origin rpy="0 0 0" xyz="0 0 0"/>
      <mass value="0.98"/>
      <inertia ixx="1e-3" ixy="0.0" ixz="0.0" iyy="1e-3" iyz="0.0" izz="1e-3"/>
    </inertial>
  </link>
  <joint name="leg0-fr_foot_joint" type="fixed">
    <origin rpy="0 0 0" xyz="0 0 -0.32"/>
    <parent link="fr_4"/>
    <child link="fr_foot"/>
  </joint>
  <link name="fr_foot">
    <inertial>
      <origin rpy="0 0 0" xyz="0 0 0"/>
      <mass value="0.01"/>
      <inertia ixx="1e-3" ixy="0.0" ixz="0.0" iyy="1e-3" iyz="0.0" izz="1e-3"/>
    </inertial>
  </link>
  <!-- <xacro:leg_transmission name="${name}"/> -->
  <joint name="leg1-fl_1_joint" type="revolute">
    <origin rpy="0 0 0" xyz="0.0 0.0875 0.0"/>
    <parent link="trunk"/>
    <child link="fl_1"/>
    <axis xyz="0 1 0"/>
    <dynamics damping="0" friction="0"/>
    <limit effort="100" lower="-3.490658503988659" upper="3.490658503988659" velocity="30"/>
  </joint>
  <link name="fl_1">
    <visual>
      <origin rpy="0 0 0" xyz="0 0 0"/>
      <geometry>
        <mesh filename="meshes/fl_1.STL" scale="1 1 1"/>
      </geometry>
    </visual>
    <collision>
      <origin rpy="0 0 0" xyz="0 0 0"/>
      <geometry>
        <mesh filename="meshes/fl_1.STL" scale="1 1 1"/>
      </geometry>
    </collision>
    <inertial>
      <origin rpy="0 0 0" xyz="0 0 0"/>
      <mass value="1.35"/>
      <inertia ixx="1e-3" ixy="0.0" ixz="0.0" iyy="1e-3" iyz="0.0" izz="1e-3"/>
    </inertial>
  </link>
  <joint name="leg1-fl_2_joint" type="revolute">
    <origin rpy="0 0 0" xyz="0 0.0775 0"/>
    <parent link="fl_1"/>
    <child link="fl_2"/>
    <axis xyz="1 0 0"/>
    <dynamics damping="0" friction="0"/>
    <limit effort="100" lower="-3.490658503988659" upper="3.490658503988659" velocity="30"/>
  </joint>
  <link name="fl_2">
    <visual>
      <origin rpy="0 0 0" xyz="0 0 0"/>
      <geometry>
        <mesh filename="meshes/fl_2.STL" scale="1 1 1"/>
      </geometry>
    </visual>
    <collision>
      <origin rpy="0 0 0" xyz="0 0 0"/>
      <geometry>
        <mesh filename="meshes/fl_2.STL" scale="1 1 1"/>
      </geometry>
    </collision>
    <inertial>
      <origin rpy="0 0 0" xyz="0 0 0"/>
      <mass value="0.9"/>
      <inertia ixx="1e-3" ixy="0.0" ixz="0.0" iyy="1e-3" iyz="0.0" izz="1e-3"/>
    </inertial>
  </link>
  <joint name="leg1-fl_3_joint" type="fixed">
    <origin rpy="0 0 0" xyz="0 0 -0.095"/>
    <parent link="fl_2"/>
    <child link="fl_3"/>
    &gt;

  </joint>
  <link name="fl_3">
    <visual>
      <origin rpy="0 0 0" xyz="0 0 0"/>
      <geometry>
        <mesh filename="meshes/fl_3.STL" scale="1 1 1"/>
      </geometry>
    </visual>
    <collision>
      <origin rpy="0 0 0" xyz="0 0 0"/>
      <geometry>
        <mesh filename="meshes/fl_3.STL" scale="1 1 1"/>
      </geometry>
    </collision>
    <inertial>
      <origin rpy="0 0 0" xyz="0 0 -0.10725"/>
      <mass value="1.7"/>
      <inertia ixx="1e-3" ixy="0.0" ixz="0.0" iyy="1e-3" iyz="0.0" izz="1e-3"/>
    </inertial>
  </link>
  <joint name="leg1-fl_4_joint" type="revolute">
    <origin rpy="0 0 0" xyz="0 0 -0.2145"/>
    <parent link="fl_3"/>
    <child link="fl_4"/>
    <axis xyz="0 1 0"/>
    <dynamics damping="0" friction="0"/>
    <limit effort="100" lower="-3.490658503988659" upper="3.490658503988659" velocity="30"/>
  </joint>
  <link name="fl_4">
    <visual>
      <origin rpy="0 0 0" xyz="0 0 0"/>
      <geometry>
        <mesh filename="meshes/fl_4.STL" scale="1 1 1"/>
      </geometry>
    </visual>
    <collision>
      <origin rpy="0 0 0" xyz="0 0 0"/>
      <geometry>
        <mesh filename="meshes/fl_4.STL" scale="1 1 1"/>
      </geometry>
    </collision>
    <inertial>
      <origin rpy="0 0 0" xyz="0 0 -0.11875"/>
      <mass value="2.1500000000000004"/>
      <inertia ixx="1e-3" ixy="0.0" ixz="0.0" iyy="1e-3" iyz="0.0" izz="1e-3"/>
    </inertial>
  </link>
  <joint name="leg1-fl_5_joint" type="fixed">
    <origin rpy="0 0 0" xyz="-0.0225 -0.03 -0.2375"/>
    <parent link="fl_4"/>
    <child link="fl_5"/>
  </joint>
  <link name="fl_5">
    <visual>
      <origin rpy="0 0 0" xyz="0 0 0"/>
      <geometry>
        <mesh filename="meshes/fl_5.STL" scale="1 1 1"/>
      </geometry>
    </visual>
    <collision>
      <origin rpy="0 0 0" xyz="0 0 0"/>
      <geometry>
        <mesh filename="meshes/fl_5.STL" scale="1 1 1"/>
      </geometry>
    </collision>
    <inertial>
      <origin rpy="0 0 0" xyz="0 0 0"/>
      <mass value="0.48000000000000004"/>
      <inertia ixx="1e-3" ixy="0.0" ixz="0.0" iyy="1e-3" iyz="0.0" izz="1e-3"/>
    </inertial>
  </link>
  <joint name="leg1-fl_6_joint" type="fixed">
    <origin rpy="0 0 0" xyz="0 0 0.0405"/>
    <parent link="fl_5"/>
    <child link="fl_6"/>
  </joint>
  <link name="fl_6">
    <visual>
      <origin rpy="0 0 0" xyz="0 0 0"/>
      <geometry>
        <mesh filename="meshes/fl_6.STL" scale="1 1 1"/>
      </geometry>
    </visual>
    <collision>
      <origin rpy="0 0 0" xyz="0 0 0"/>
      <geometry>
        <mesh filename="meshes/fl_6.STL" scale="1 1 1"/>
      </geometry>
    </collision>
    <inertial>
      <origin rpy="0 0 0" xyz="0 0 0"/>
      <mass value="0.98"/>
      <inertia ixx="1e-3" ixy="0.0" ixz="0.0" iyy="1e-3" iyz="0.0" izz="1e-3"/>
    </inertial>
  </link>
  <joint name="leg1-fl_foot_joint" type="fixed">
    <origin rpy="0 0 0" xyz="0 0 -0.32"/>
    <parent link="fl_4"/>
    <child link="fl_foot"/>
  </joint>
  <link name="fl_foot">
    <inertial>
      <origin rpy="0 0 0" xyz="0 0 0"/>
      <mass value="0.01"/>
      <inertia ixx="1e-3" ixy="0.0" ixz="0.0" iyy="1e-3" iyz="0.0" izz="1e-3"/>
    </inertial>
  </link>
  <!-- <xacro:leg_transmission name="${name}"/> -->
  <joint name="leg2-hr_1_joint" type="revolute">
    <origin rpy="0 0 0" xyz="-0.375 -0.0875 -0.18"/>
    <parent link="trunk"/>
    <child link="hr_1"/>
    <axis xyz="0 1 0"/>
    <dynamics damping="0" friction="0"/>
    <limit effort="100" lower="-3.490658503988659" upper="3.490658503988659" velocity="30"/>
  </joint>
  <link name="hr_1">
    <visual>
      <origin rpy="0 0 0" xyz="0 0 0"/>
      <geometry>
        <mesh filename="meshes/hr_a.STL" scale="1 1 1"/>
      </geometry>
    </visual>
    <collision>
      <origin rpy="0 0 0" xyz="0 0 0"/>
      <geometry>
        <mesh filename="meshes/hr_a.STL" scale="1 1 1"/>
      </geometry>
    </collision>
    <inertial>
      <origin rpy="0 0 0" xyz="0 0 0"/>
      <mass value="0.5"/>
      <inertia ixx="1e-3" ixy="0.0" ixz="0.0" iyy="1e-3" iyz="0.0" izz="1e-3"/>
    </inertial>
  </link>
  <joint name="leg2-hr_2_joint" type="revolute">
    <origin rpy="0 0 0" xyz="0 -0.0775 0"/>
    <parent link="hr_1"/>
    <child link="hr_2"/>
    <axis xyz="1 0 0"/>
    <dynamics damping="0" friction="0"/>
    <limit effort="100" lower="-3.490658503988659" upper="3.490658503988659" velocity="30"/>
  </joint>
  <link name="hr_2">
    <visual>
      <origin rpy="0 0 0" xyz="0 0 0"/>
      <geometry>
        <mesh filename="meshes/hr_h.STL" scale="1 1 1"/>
      </geometry>
    </visual>
    <collision>
      <origin rpy="0 0 0" xyz="0 0 0"/>
      <geometry>
        <mesh filename="meshes/hr_h.STL" scale="1 1 1"/>
      </geometry>
    </collision>
    <inertial>
      <origin rpy="0 0 0" xyz="0 0 -0.1125"/>
      <mass value="1.55"/>
      <inertia ixx="1e-3" ixy="0.0" ixz="0.0" iyy="1e-3" iyz="0.0" izz="1e-3"/>
    </inertial>
  </link>
  <joint name="leg2-hr_3_joint" type="revolute">
    <origin rpy="0 0 0" xyz="0 0 -0.225"/>
    <parent link="hr_2"/>
    <child link="hr_3"/>
    <axis xyz="0 1 0"/>
    <dynamics damping="0" friction="0"/>
    <limit effort="100" lower="-3.490658503988659" upper="3.490658503988659" velocity="30"/>
  </joint>
  <link name="hr_3">
    <visual>
      <origin rpy="0 0 0" xyz="0 0 0"/>
      <geometry>
        <mesh filename="meshes/hr_k.STL" scale="1 1 1"/>
      </geometry>
    </visual>
    <collision>
      <origin rpy="0 0 0" xyz="0 0 0"/>
      <geometry>
        <mesh filename="meshes/hr_k.STL" scale="1 1 1"/>
      </geometry>
    </collision>
    <inertial>
      <origin rpy="0 0 0" xyz="0 0 -0.1"/>
      <mass value="1.4500000000000002"/>
      <inertia ixx="1e-3" ixy="0.0" ixz="0.0" iyy="1e-3" iyz="0.0" izz="1e-3"/>
    </inertial>
  </link>
  <joint name="leg2-hr_4_continuous" type="fixed">
    <origin rpy="0 0 0" xyz="-0.01 -0.053 -0.0"/>
    <parent link="hr_3"/>
    <child link="hr_4"/>
    <axis xyz="0 1 0"/>
    <dynamics damping="0" friction="0"/>
    <limit effort="100" velocity="30"/>
  </joint>
  <link name="hr_4">
    <visual>
      <origin rpy="3.141592653589793 0 0" xyz="0 0 0"/>
      <geometry>
        <mesh filename="meshes/hr_kw.STL" scale="1 1 1"/>
      </geometry>
    </visual>
    <collision>
      <origin rpy="3.141592653589793 0 0" xyz="0 0 0"/>
      <geometry>
        <mesh filename="meshes/hr_kw.STL" scale="1 1 1"/>
      </geometry>
    </collision>
    <inertial>
      <origin rpy="0 0 0" xyz="0 0 0"/>
      <mass value="0.5"/>
      <inertia ixx="1e-3" ixy="0.0" ixz="0.0" iyy="2e-3" iyz="0.0" izz="1e-3"/>
    </inertial>
  </link>
  <joint name="leg2-hr_5_continuous" type="fixed">
    <origin rpy="0 0 0" xyz="-0.01 0 -0.2"/>
    <parent link="hr_3"/>
    <child link="hr_5"/>
    <axis xyz="0 1 0"/>
    <dynamics damping="0" friction="0"/>
    <limit effort="100" velocity="30"/>
  </joint>
  <link name="hr_5">
    <visual>
      <origin rpy="3.141592653589793 0 0" xyz="0 0 0"/>
      <geometry>
        <mesh filename="meshes/hr_fw.STL" scale="1 1 1"/>
      </geometry>
    </visual>
    <collision>
      <origin rpy="3.141592653589793 0 0" xyz="0 0 0"/>
      <geometry>
        <mesh filename="meshes/hr_fw.STL" scale="1 1 1"/>
      </geometry>
    </collision>
    <inertial>
      <origin rpy="0 0 0" xyz="0 0 0"/>
      <mass value="0.5"/>
      <inertia ixx="1e-3" ixy="0.0" ixz="0.0" iyy="2e-3" iyz="0.0" izz="1e-3"/>
    </inertial>
  </link>
  <joint name="leg2-hr_foot_joint" type="fixed">
    <origin rpy="0 0 0" xyz="0 0 -0.06"/>
    <parent link="hr_5"/>
    <child link="hr_foot"/>
  </joint>
  <link name="hr_foot">
    <inertial>
      <origin rpy="0 0 0" xyz="0 0 0"/>
      <mass value="0.01"/>
      <inertia ixx="1e-3" ixy="0.0" ixz="0.0" iyy="1e-3" iyz="0.0" izz="1e-3"/>
    </inertial>
  </link>
  <!-- <xacro:leg_transmission name="${name}"/> -->
  <joint name="leg3-hl_1_joint" type="revolute">
    <origin rpy="0 0 0" xyz="-0.375 0.0875 -0.18"/>
    <parent link="trunk"/>
    <child link="hl_1"/>
    <axis xyz="0 1 0"/>
    <dynamics damping="0" friction="0"/>
    <limit effort="100" lower="-3.490658503988659" upper="3.490658503988659" velocity="30"/>
  </joint>
  <link name="hl_1">
    <visual>
      <origin rpy="0 0 0" xyz="0 0 0"/>
      <geometry>
        <mesh filename="meshes/hl_a.STL" scale="1 1 1"/>
      </geometry>
    </visual>
    <collision>
      <origin rpy="0 0 0" xyz="0 0 0"/>
      <geometry>
        <mesh filename="meshes/hl_a.STL" scale="1 1 1"/>
      </geometry>
    </collision>
    <inertial>
      <origin rpy="0 0 0" xyz="0 0 0"/>
      <mass value="0.5"/>
      <inertia ixx="1e-3" ixy="0.0" ixz="0.0" iyy="1e-3" iyz="0.0" izz="1e-3"/>
    </inertial>
  </link>
  <joint name="leg3-hl_2_joint" type="revolute">
    <origin rpy="0 0 0" xyz="0 0.0775 0"/>
    <parent link="hl_1"/>
    <child link="hl_2"/>
    <axis xyz="1 0 0"/>
    <dynamics damping="0" friction="0"/>
    <limit effort="100" lower="-3.490658503988659" upper="3.490658503988659" velocity="30"/>
  </joint>
  <link name="hl_2">
    <visual>
      <origin rpy="0 0 0" xyz="0 0 0"/>
      <geometry>
        <mesh filename="meshes/hl_h.STL" scale="1 1 1"/>
      </geometry>
    </visual>
    <collision>
      <origin rpy="0 0 0" xyz="0 0 0"/>
      <geometry>
        <mesh filename="meshes/hl_h.STL" scale="1 1 1"/>
      </geometry>
    </collision>
    <inertial>
      <origin rpy="0 0 0" xyz="0 0 -0.1125"/>
      <mass value="1.55"/>
      <inertia ixx="1e-3" ixy="0.0" ixz="0.0" iyy="1e-3" iyz="0.0" izz="1e-3"/>
    </inertial>
  </link>
  <joint name="leg3-hl_3_joint" type="revolute">
    <origin rpy="0 0 0" xyz="0 0 -0.225"/>
    <parent link="hl_2"/>
    <child link="hl_3"/>
    <axis xyz="0 1 0"/>
    <dynamics damping="0" friction="0"/>
    <limit effort="100" lower="-3.490658503988659" upper="3.490658503988659" velocity="30"/>
  </joint>
  <link name="hl_3">
    <visual>
      <origin rpy="0 0 0" xyz="0 0 0"/>
      <geometry>
        <mesh filename="meshes/hl_k.STL" scale="1 1 1"/>
      </geometry>
    </visual>
    <collision>
      <origin rpy="0 0 0" xyz="0 0 0"/>
      <geometry>
        <mesh filename="meshes/hl_k.STL" scale="1 1 1"/>
      </geometry>
    </collision>
    <inertial>
      <origin rpy="0 0 0" xyz="0 0 -0.1"/>
      <mass value="1.4500000000000002"/>
      <inertia ixx="1e-3" ixy="0.0" ixz="0.0" iyy="1e-3" iyz="0.0" izz="1e-3"/>
    </inertial>
  </link>
  <joint name="leg3-hl_4_continuous" type="fixed">
    <origin rpy="0 0 0" xyz="-0.01 0.053 -0.0"/>
    <parent link="hl_3"/>
    <child link="hl_4"/>
    <axis xyz="0 1 0"/>
    <dynamics damping="0" friction="0"/>
    <limit effort="100" velocity="30"/>
  </joint>
  <link name="hl_4">
    <visual>
      <origin rpy="0 0 0" xyz="0 0 0"/>
      <geometry>
        <mesh filename="meshes/hl_kw.STL" scale="1 1 1"/>
      </geometry>
    </visual>
    <collision>
      <origin rpy="0 0 0" xyz="0 0 0"/>
      <geometry>
        <mesh filename="meshes/hl_kw.STL" scale="1 1 1"/>
      </geometry>
    </collision>
    <inertial>
      <origin rpy="0 0 0" xyz="0 0 0"/>
      <mass value="0.5"/>
      <inertia ixx="1e-3" ixy="0.0" ixz="0.0" iyy="2e-3" iyz="0.0" izz="1e-3"/>
    </inertial>
  </link>
  <joint name="leg3-hl_5_continuous" type="fixed">
    <origin rpy="0 0 0" xyz="-0.01 0 -0.2"/>
    <parent link="hl_3"/>
    <child link="hl_5"/>
    <axis xyz="0 1 0"/>
    <dynamics damping="0" friction="0"/>
    <limit effort="100" velocity="30"/>
  </joint>
  <link name="hl_5">
    <visual>
      <origin rpy="0 0 0" xyz="0 0 0"/>
      <geometry>
        <mesh filename="meshes/hl_fw.STL" scale="1 1 1"/>
      </geometry>
    </visual>
    <collision>
      <origin rpy="0 0 0" xyz="0 0 0"/>
      <geometry>
        <mesh filename="meshes/hl_fw.STL" scale="1 1 1"/>
      </geometry>
    </collision>
    <inertial>
      <origin rpy="0 0 0" xyz="0 0 0"/>
      <mass value="0.5"/>
      <inertia ixx="1e-3" ixy="0.0" ixz="0.0" iyy="2e-3" iyz="0.0" izz="1e-3"/>
    </inertial>
  </link>
  <joint name="leg3-hl_foot_joint" type="fixed">
    <origin rpy="0 0 0" xyz="0 0 -0.06"/>
    <parent link="hl_5"/>
    <child link="hl_foot"/>
  </joint>
  <link name="hl_foot">
    <inertial>
      <origin rpy="0 0 0" xyz="0 0 0"/>
      <mass value="0.01"/>
      <inertia ixx="1e-3" ixy="0.0" ixz="0.0" iyy="1e-3" iyz="0.0" izz="1e-3"/>
    </inertial>
  </link>
  <!-- <xacro:leg_transmission name="${name}"/> -->
</robot>
